<?xml version="1.0"?>
<robot name="arm">

  <link name="base_link">
    <visual>
      <geometry>
        <cylinder length="0.01" radius="0.05"/>
      </geometry>
      <material name="white">
        <color rgba="1 1 1 1"/>
      </material>
    </visual>
  </link>

  <link name="link_1">
    <visual>
      <geometry>
       <sphere radius="0.03"/>
      </geometry>
      <material name="gray">
        <color rgba="0.2 0.2 0.2 1"/>
      </material>
        <origin xyz="0 0 0" rpy = "0 0 0"/>
    </visual>
  </link>

  <link name="link_2">
     <visual>
      <geometry>
        <cylinder length="0.203" radius = "0.01"/>
<<<<<<< HEAD
=======
      </geometry>
      <material name="white">
        <color rgba="1 1 1 1"/>
      </material>
      <origin xyz="0 0 0.1015" rpy = "0 0 0"/>
    </visual>
  </link>

  <link name="link_2_3">
    <visual>
      <geometry>
       <sphere radius="0.03"/>
      </geometry>
      <material name="gray">
        <color rgba="0.2 0.2 0.2 1"/>
      </material>
        <origin xyz="0 0 0" rpy = "0 0 0"/>
    </visual>
  </link>
  
  <link name="link_3">
    <visual>
      <geometry>
        <cylinder length="0.203" radius = "0.01"/>
>>>>>>> b905b77b82c825acc52fec53f1bad424679cbb6a
      </geometry>
      <material name="white">
        <color rgba="1 1 1 1"/>
      </material>
      <origin xyz="0 0 0.1015" rpy = "0 0 0"/>
    </visual>
  </link>

<<<<<<< HEAD
  <link name="link_2_3">
    <visual>
      <geometry>
       <sphere radius="0.03"/>
      </geometry>
      <material name="gray">
        <color rgba="0.2 0.2 0.2 1"/>
      </material>
        <origin xyz="0 0 0" rpy = "0 0 0"/>
    </visual>
  </link>
  
  <link name="link_3">
    <visual>
      <geometry>
        <cylinder length="0.203" radius = "0.01"/>
      </geometry>
      <material name="white">
        <color rgba="1 1 1 1"/>
      </material>
      <origin xyz="0 0 0.1015" rpy = "0 0 0"/>
    </visual>
  </link>

=======
>>>>>>> b905b77b82c825acc52fec53f1bad424679cbb6a
  <link name="link_3_4">
      <visual>
        <geometry>
         <sphere radius="0.03"/>
        </geometry>
        <material name="gray">
          <color rgba="0.2 0.2 0.2 1"/>
        </material>
          <origin xyz="0 0 0" rpy = "0 0 0"/>
      </visual>
  </link>
  
  <link name="link_4">
    <visual>
      <geometry>
        <cylinder length="0.05" radius = "0.01"/>
      </geometry>
      <material name="white">
        <color rgba="1 1 1 1"/>
      </material>
      <origin xyz="0 0 0.025" rpy = "0 0 0"/>
    </visual>
  </link>

  <link name="link_4_5">
      <visual>
        <geometry>
         <sphere radius="0.03"/>
        </geometry>
        <material name="gray">
          <color rgba="0.2 0.2 0.2 1"/>
        </material>
          <origin xyz="0 0 0" rpy = "0 0 0"/>
      </visual>
  </link>

  <link name="link_5">
    <visual>
      <geometry>
        <cylinder length="0.15" radius = "0.01"/>
<<<<<<< HEAD
=======
      </geometry>
      <material name="white">
        <color rgba="1 1 1 1"/>
      </material>
      <origin xyz="0 0 0.075" rpy = "0 0 0"/>
    </visual>
  </link>

  <link name="link_5_6">
      <visual>
        <geometry>
         <sphere radius="0.03"/>
        </geometry>
        <material name="gray">
          <color rgba="0.2 0.2 0.2 1"/>
        </material>
          <origin xyz="0 0 0" rpy = "0 0 0"/>
      </visual>
  </link>
  
  <link name="link_6">
    <visual>
      <geometry>
        <!-- Длина равна макс. вылету ползунка (0.1), радиус чуть меньше (поршень) -->
        <cylinder length="0.1" radius="0.008"/>
>>>>>>> b905b77b82c825acc52fec53f1bad424679cbb6a
      </geometry>
      <material name="white">
        <color rgba="1 1 1 1"/>
      </material>
<<<<<<< HEAD
      <origin xyz="0 0 0.075" rpy = "0 0 0"/>
    </visual>
  </link>

  <link name="link_5_6">
      <visual>
        <geometry>
         <sphere radius="0.03"/>
        </geometry>
        <material name="gray">
          <color rgba="0.2 0.2 0.2 1"/>
        </material>
          <origin xyz="0 0 0" rpy = "0 0 0"/>
      </visual>
  </link>
  
  <link name="link_6">
    <visual>
      <geometry>
        <!-- Длина равна макс. вылету ползунка (0.1), радиус чуть меньше (поршень) -->
        <cylinder length="0.1" radius="0.008"/>
      </geometry>
      <material name="white">
        <color rgba="1 1 1 1"/>
      </material>
      <!-- Смещаем геометрию вниз в трубу 5-го звена, чтобы не было разрыва -->
      <origin xyz="0 0 -0.05" rpy = "0 0 0"/>
    </visual>
  </link>

=======
      <!-- Смещаем геометрию вниз в трубу 5-го звена, чтобы не было разрыва -->
      <origin xyz="0 0 -0.05" rpy = "0 0 0"/>
    </visual>
  </link>

>>>>>>> b905b77b82c825acc52fec53f1bad424679cbb6a
  <link name="tool0"/>

  <joint name="joint_1" type="revolute">
    <axis xyz="0 0 1"/>
    <parent link="base_link"/>
    <child link="link_1"/>
    <origin xyz="0 0 0" rpy = "0 0 0"/>
    <limit effort="1000.0" lower="-1.62" upper="1.62" velocity="0.5"/>
  </joint>
  
  <joint name="joint_2" type="revolute">
    <axis xyz="0 1 0"/>
    <parent link="link_1"/>
    <child link="link_2"/>
    <origin xyz="0 0 0" rpy = "0 0 0"/>
    <limit effort="1000.0" lower="-0.96" upper="2.182" velocity="0.5"/>
  </joint>

  <joint name="joint_3" type="revolute">
    <axis xyz="0 1 0"/>
    <parent link="link_2"/>
    <child link="link_3"/>
    <origin xyz="0 0 0.203" rpy = "0 0 0"/>
    <limit effort="1000.0" lower="-0.96" upper="2.182" velocity="0.5"/>
  </joint>

  <joint name="joint_4" type="revolute">
    <axis xyz="0 0 1"/>
    <parent link="link_3"/>
    <child link="link_4"/>
    <origin xyz="0 0 0.203" rpy = "0 0 0"/>
    <limit effort="1000.0" lower="-3.14" upper="3.14" velocity="0.5"/>
  </joint>

  <joint name="joint_5" type="revolute">
    <axis xyz="0 1 0"/>
    <parent link="link_4"/>
    <child link="link_5"/>
    <origin xyz="0 0 0.05" rpy = "0 0 0"/>
    <limit effort="1000.0" lower="-2.2" upper="2.2" velocity="0.5"/>
  </joint>

  <joint name="joint_6" type="prismatic">
    <axis xyz="0 0 1"/>
    <parent link="link_5"/>
    <child link="link_6"/>
    <origin xyz="0 0 0.15" rpy = "0 0 0"/>
    <limit effort="1000.0" lower="0" upper="0.1" velocity="0.5"/>
  </joint>
<<<<<<< HEAD

  <joint name="joint_tool0" type="fixed">
    <parent link="link_6"/>
    <child link="tool0"/>
    <origin xyz="0 0 0" rpy = "0 0 0"/>
  </joint>

  <joint name="joint_2_3" type="fixed">
    <parent link="link_2"/>
    <child link="link_2_3"/>
    <origin xyz="0 0 0.203" rpy = "0 0 0"/>
  </joint>

=======

  <joint name="joint_tool0" type="fixed">
    <parent link="link_6"/>
    <child link="tool0"/>
    <origin xyz="0 0 0" rpy = "0 0 0"/>
  </joint>

  <joint name="joint_2_3" type="fixed">
    <parent link="link_2"/>
    <child link="link_2_3"/>
    <origin xyz="0 0 0.203" rpy = "0 0 0"/>
  </joint>

>>>>>>> b905b77b82c825acc52fec53f1bad424679cbb6a
  <joint name="joint_3_4" type="fixed">
    <parent link="link_3"/>
    <child link="link_3_4"/>
    <origin xyz="0 0 0.203" rpy = "0 0 0"/>
  </joint>

  <joint name="joint_4_5" type="fixed">
    <parent link="link_4"/>
    <child link="link_4_5"/>
    <origin xyz="0 0 0.05" rpy = "0 0 0"/>
  </joint>

  <joint name="joint_5_6" type="fixed">
    <parent link="link_5"/>
    <child link="link_5_6"/>
    <origin xyz="0 0 0.15" rpy = "0 0 0"/>
  </joint>

</robot>